Workbook

Sheet Assumptions
A1: Heartbeat: 18-month plan, key assumptions
A2: Blue = input you can change. Yellow = key lever. All money in ₹ (INR), monthly unless noted. Every other sheet recalculates from these cells.
A4: Funding
A5: Raise amount | B5: 7500000 | C5: Proposed angel round. Founder's decision; ₹75 L gives ~18 months of runway at these costs.
A6: Timeline (month number)
A7: Build phase ends (Phases 0–4 of the plan) | B7: 3 | C7: docs/DATING_PLAN.md §10
A8: Closed beta ends (one city, invite-only) | B8: 6 | C8: docs/DATING_PLAN.md §10
A9: Bengaluru public launch ends | B9: 12 | C9: After this month the plan adds a second city
A10: Premium (Heartbeat+) starts in month | B10: 7 | C10: Premium switched on at public launch
A11: Team (monthly cost)
A12: Founder salary | B12: 50000 | C12: Below-market founder pay; founder's estimate
A13: Full-stack developer, from month | B13: 1
A14: Full-stack developer salary | B14: 110000 | C14: Estimate for a mid-level React/Node developer in Bengaluru (CTC/12)
A15: Community and safety lead, from month | B15: 4 | C15: Manual photo review, reports, beta community. Needed from beta
A16: Community and safety lead salary | B16: 45000 | C16: Estimate
A17: Content writer (part-time), from month | B17: 1 | C17: Writes question packs in English and Hinglish
A18: Content writer cost | B18: 25000 | C18: Estimate, part-time
A19: Marketing (monthly spend)
A20: Build phase (waitlist) | B20: 20000 | C20: Waitlist page, Instagram, college groups
A21: Closed beta | B21: 100000 | C21: Campus ambassadors, mixers, referral rewards
A22: Bengaluru launch | B22: 120000 | C22: Paid social, events, creator collabs
A23: Second city | B23: 150000 | C23: Launch in second city plus Bengaluru upkeep
A24: Running costs
A25: Infrastructure base (Firebase, Vercel Pro, Cloudinary, Sentry) | B25: 8000 | C25: Estimate; Vercel Pro is about US$20/month
A26: Infrastructure per monthly active user | B26: 2 | C26: Estimate: Firestore reads, image delivery, push
A27: Legal and company setup (one-time, month 1) | B27: 250000 | C27: Incorporation, terms and privacy review, DPDP and IT Rules setup, trademark
A28: Accounting and compliance retainer | B28: 15000 | C28: CA retainer, GST filings
A29: Tools, devices and misc | B29: 10000 | C29: Test phones, software subscriptions
A30: Growth
A31: New signups per month: closed beta | B31: 700 | C31: Invite-only; capped by manual photo review
A32: New signups per month: Bengaluru launch | B32: 2000 | C32: Assumption to test in beta
A33: New signups per month: second city | B33: 4500 | C33: Two cities combined
A34: Monthly active users as % of total signups | B34: 0.4 | C34: Assumption
A35: Paying users as % of monthly active users | B35: 0.05 | C35: Low end of the 5–15% Redseer reports for Indian dating apps at market prices (Dec 2025)
A36: Monthly plan price (incl. GST) | B36: 499 | C36: Set below Bumble Premium ₹799 and Hinge+ ₹1,199, above QuackQuack's ₹299–589 tests (App Store India, Oct 2026). 3-month plan ~₹1,299
A37: Weekly plan price (incl. GST) | B37: 149 | C37: Between Aisle/Happn ₹99 a week and Bumble ₹279–399 a week (App Store India, Oct 2026)
A38: Share of paying users on weekly plans | B38: 0.4 | C38: Assumption: weekly 'sachet' plans are mainstream in India (Bumble, Aisle, Happn, TrulyMadly all sell them)
A39: Weekly passes bought per weekly buyer per month | B39: 2 | C39: Assumption: many weekly buyers don't renew every week
A40: Average revenue per paying user per month (incl. GST) | B40: =Assumptions!$B$38*Assumptions!$B$37*Assumptions!$B$39+(1-Assumptions!$B$38)*Assumptions!$B$36 | C40: Calculated: weekly share × weekly price × passes + monthly share × monthly price. Store prices imply ₹300–900 for Indian apps
A41: GST on subscriptions | B41: 0.18 | C41: 18% GST on online services; prices are GST-inclusive
...

Sheet Monthly
A1: Monthly plan (₹)
A2: Calculated from the Assumptions sheet. Don't type here; change the inputs instead.
A4: Month | B4: 1 | C4: 2 | D4: 3 | E4: 4 | F4: 5 | G4: 6 | H4: 7 | I4: 8 | J4: 9 | K4: 10 | L4: 11 | M4: 12 | N4: 13 | O4: 14 | P4: 15 | Q4: 16 | R4: 17 | S4: 18 | T4: Total
A5: Phase | B5: =IF(B$4<=Assumptions!$B$7,"Build",IF(B$4<=Assumptions!$B$8,"Closed beta",IF(B$4<=Assumptions!$B$9,"Bengaluru","City 2"))) | C5: =IF(C$4<=Assumptions!$B$7,"Build",IF(C$4<=Assumptions!$B$8,"Closed beta",IF(C$4<=Assumptions!$B$9,"Bengaluru","City 2"))) | D5: =IF(D$4<=Assumptions!$B$7,"Build",IF(D$4<=Assumptions!$B$8,"Closed beta",IF(D$4<=Assumptions!$B$9,"Bengaluru","City 2"))) | E5: =IF(E$4<=Assumptions!$B$7,"Build",IF(E$4<=Assumptions!$B$8,"Closed beta",IF(E$4<=Assumptions!$B$9,"Bengaluru","City 2"))) | F5: =IF(F$4<=Assumptions!$B$7,"Build",IF(F$4<=Assumptions!$B$8,"Closed beta",IF(F$4<=Assumptions!$B$9,"Bengaluru","City 2"))) | G5: =IF(G$4<=Assumptions!$B$7,"Build",IF(G$4<=Assumptions!$B$8,"Closed beta",IF(G$4<=Assumptions!$B$9,"Bengaluru","City 2"))) | H5: =IF(H$4<=Assumptions!$B$7,"Build",IF(H$4<=Assumptions!$B$8,"Closed beta",IF(H$4<=Assumptions!$B$9,"Bengaluru","City 2"))) | I5: =IF(I$4<=Assumptions!$B$7,"Build",IF(I$4<=Assumptions!$B$8,"Closed beta",IF(I$4<=Assumptions!$B$9,"Bengaluru","City 2"))) | ... S5: =IF(S$4<=Assumptions!$B$7,"Build",IF(S$4<=Assumptions!$B$8,"Closed beta",IF(S$4<=Assumptions!$B$9,"Bengaluru","City 2")))
A6: Costs
A7: Founder | B7: =Assumptions!$B$12 | C7: =Assumptions!$B$12 | D7: =Assumptions!$B$12 | E7: =Assumptions!$B$12 | F7: =Assumptions!$B$12 | G7: =Assumptions!$B$12 | H7: =Assumptions!$B$12 | I7: =Assumptions!$B$12 | ... S7: =Assumptions!$B$12 | T7: =SUM(B7:S7)
A8: Full-stack developer | B8: =IF(B$4>=Assumptions!$B$13,Assumptions!$B$14,0) | C8: =IF(C$4>=Assumptions!$B$13,Assumptions!$B$14,0) | D8: =IF(D$4>=Assumptions!$B$13,Assumptions!$B$14,0) | E8: =IF(E$4>=Assumptions!$B$13,Assumptions!$B$14,0) | F8: =IF(F$4>=Assumptions!$B$13,Assumptions!$B$14,0) | G8: =IF(G$4>=Assumptions!$B$13,Assumptions!$B$14,0) | H8: =IF(H$4>=Assumptions!$B$13,Assumptions!$B$14,0) | I8: =IF(I$4>=Assumptions!$B$13,Assumptions!$B$14,0) | ... S8: =IF(S$4>=Assumptions!$B$13,Assumptions!$B$14,0) | T8: =SUM(B8:S8)
A9: Community and safety lead | B9: =IF(B$4>=Assumptions!$B$15,Assumptions!$B$16,0) | C9: =IF(C$4>=Assumptions!$B$15,Assumptions!$B$16,0) | D9: =IF(D$4>=Assumptions!$B$15,Assumptions!$B$16,0) | E9: =IF(E$4>=Assumptions!$B$15,Assumptions!$B$16,0) | F9: =IF(F$4>=Assumptions!$B$15,Assumptions!$B$16,0) | G9: =IF(G$4>=Assumptions!$B$15,Assumptions!$B$16,0) | H9: =IF(H$4>=Assumptions!$B$15,Assumptions!$B$16,0) | I9: =IF(I$4>=Assumptions!$B$15,Assumptions!$B$16,0) | ... S9: =IF(S$4>=Assumptions!$B$15,Assumptions!$B$16,0) | T9: =SUM(B9:S9)
A10: Content writer | B10: =IF(B$4>=Assumptions!$B$17,Assumptions!$B$18,0) | C10: =IF(C$4>=Assumptions!$B$17,Assumptions!$B$18,0) | D10: =IF(D$4>=Assumptions!$B$17,Assumptions!$B$18,0) | E10: =IF(E$4>=Assumptions!$B$17,Assumptions!$B$18,0) | F10: =IF(F$4>=Assumptions!$B$17,Assumptions!$B$18,0) | G10: =IF(G$4>=Assumptions!$B$17,Assumptions!$B$18,0) | H10: =IF(H$4>=Assumptions!$B$17,Assumptions!$B$18,0) | I10: =IF(I$4>=Assumptions!$B$17,Assumptions!$B$18,0) | ... S10: =IF(S$4>=Assumptions!$B$17,Assumptions!$B$18,0) | T10: =SUM(B10:S10)
A11: Marketing | B11: =IF(B$4<=Assumptions!$B$7,Assumptions!$B$20,IF(B$4<=Assumptions!$B$8,Assumptions!$B$21,IF(B$4<=Assumptions!$B$9,Assumptions!$B$22,Assumptions!$B$23))) | C11: =IF(C$4<=Assumptions!$B$7,Assumptions!$B$20,IF(C$4<=Assumptions!$B$8,Assumptions!$B$21,IF(C$4<=Assumptions!$B$9,Assumptions!$B$22,Assumptions!$B$23))) | D11: =IF(D$4<=Assumptions!$B$7,Assumptions!$B$20,IF(D$4<=Assumptions!$B$8,Assumptions!$B$21,IF(D$4<=Assumptions!$B$9,Assumptions!$B$22,Assumptions!$B$23))) | E11: =IF(E$4<=Assumptions!$B$7,Assumptions!$B$20,IF(E$4<=Assumptions!$B$8,Assumptions!$B$21,IF(E$4<=Assumptions!$B$9,Assumptions!$B$22,Assumptions!$B$23))) | F11: =IF(F$4<=Assumptions!$B$7,Assumptions!$B$20,IF(F$4<=Assumptions!$B$8,Assumptions!$B$21,IF(F$4<=Assumptions!$B$9,Assumptions!$B$22,Assumptions!$B$23))) | G11: =IF(G$4<=Assumptions!$B$7,Assumptions!$B$20,IF(G$4<=Assumptions!$B$8,Assumptions!$B$21,IF(G$4<=Assumptions!$B$9,Assumptions!$B$22,Assumptions!$B$23))) | H11: =IF(H$4<=Assumptions!$B$7,Assumptions!$B$20,IF(H$4<=Assumptions!$B$8,Assumptions!$B$21,IF(H$4<=Assumptions!$B$9,Assumptions!$B$22,Assumptions!$B$23))) | I11: =IF(I$4<=Assumptions!$B$7,Assumptions!$B$20,IF(I$4<=Assumptions!$B$8,Assumptions!$B$21,IF(I$4<=Assumptions!$B$9,Assumptions!$B$22,Assumptions!$B$23))) | ... S11: =IF(S$4<=Assumptions!$B$7,Assumptions!$B$20,IF(S$4<=Assumptions!$B$8,Assumptions!$B$21,IF(S$4<=Assumptions!$B$9,Assumptions!$B$22,Assumptions!$B$23))) | T11: =SUM(B11:S11)
A12: Infrastructure | B12: =Assumptions!$B$25+Assumptions!$B$26*B19 | C12: =Assumptions!$B$25+Assumptions!$B$26*C19 | D12: =Assumptions!$B$25+Assumptions!$B$26*D19 | E12: =Assumptions!$B$25+Assumptions!$B$26*E19 | F12: =Assumptions!$B$25+Assumptions!$B$26*F19 | G12: =Assumptions!$B$25+Assumptions!$B$26*G19 | H12: =Assumptions!$B$25+Assumptions!$B$26*H19 | I12: =Assumptions!$B$25+Assumptions!$B$26*I19 | ... S12: =Assumptions!$B$25+Assumptions!$B$26*S19 | T12: =SUM(B12:S12)
A13: Legal, accounting and compliance | B13: =IF(B$4=1,Assumptions!$B$27,0)+Assumptions!$B$28 | C13: =IF(C$4=1,Assumptions!$B$27,0)+Assumptions!$B$28 | D13: =IF(D$4=1,Assumptions!$B$27,0)+Assumptions!$B$28 | E13: =IF(E$4=1,Assumptions!$B$27,0)+Assumptions!$B$28 | F13: =IF(F$4=1,Assumptions!$B$27,0)+Assumptions!$B$28 | G13: =IF(G$4=1,Assumptions!$B$27,0)+Assumptions!$B$28 | H13: =IF(H$4=1,Assumptions!$B$27,0)+Assumptions!$B$28 | I13: =IF(I$4=1,Assumptions!$B$27,0)+Assumptions!$B$28 | ... S13: =IF(S$4=1,Assumptions!$B$27,0)+Assumptions!$B$28 | T13: =SUM(B13:S13)
A14: Tools, devices and misc | B14: =Assumptions!$B$29 | C14: =Assumptions!$B$29 | D14: =Assumptions!$B$29 | E14: =Assumptions!$B$29 | F14: =Assumptions!$B$29 | G14: =Assumptions!$B$29 | H14: =Assumptions!$B$29 | I14: =Assumptions!$B$29 | ... S14: =Assumptions!$B$29 | T14: =SUM(B14:S14)
A15: Total costs | B15: =B7+B8+B9+B10+B11+B13+B14+B12 | C15: =C7+C8+C9+C10+C11+C13+C14+C12 | D15: =D7+D8+D9+D10+D11+D13+D14+D12 | E15: =E7+E8+E9+E10+E11+E13+E14+E12 | F15: =F7+F8+F9+F10+F11+F13+F14+F12 | G15: =G7+G8+G9+G10+G11+G13+G14+G12 | H15: =H7+H8+H9+H10+H11+H13+H14+H12 | I15: =I7+I8+I9+I10+I11+I13+I14+I12 | ... S15: =S7+S8+S9+S10+S11+S13+S14+S12 | T15: =SUM(B15:S15)
A16: Users
A17: New signups | B17: =IF(B$4<=Assumptions!$B$7,0,IF(B$4<=Assumptions!$B$8,Assumptions!$B$31,IF(B$4<=Assumptions!$B$9,Assumptions!$B$32,Assumptions!$B$33))) | C17: =IF(C$4<=Assumptions!$B$7,0,IF(C$4<=Assumptions!$B$8,Assumptions!$B$31,IF(C$4<=Assumptions!$B$9,Assumptions!$B$32,Assumptions!$B$33))) | D17: =IF(D$4<=Assumptions!$B$7,0,IF(D$4<=Assumptions!$B$8,Assumptions!$B$31,IF(D$4<=Assumptions!$B$9,Assumptions!$B$32,Assumptions!$B$33))) | E17: =IF(E$4<=Assumptions!$B$7,0,IF(E$4<=Assumptions!$B$8,Assumptions!$B$31,IF(E$4<=Assumptions!$B$9,Assumptions!$B$32,Assumptions!$B$33))) | F17: =IF(F$4<=Assumptions!$B$7,0,IF(F$4<=Assumptions!$B$8,Assumptions!$B$31,IF(F$4<=Assumptions!$B$9,Assumptions!$B$32,Assumptions!$B$33))) | G17: =IF(G$4<=Assumptions!$B$7,0,IF(G$4<=Assumptions!$B$8,Assumptions!$B$31,IF(G$4<=Assumptions!$B$9,Assumptions!$B$32,Assumptions!$B$33))) | H17: =IF(H$4<=Assumptions!$B$7,0,IF(H$4<=Assumptions!$B$8,Assumptions!$B$31,IF(H$4<=Assumptions!$B$9,Assumptions!$B$32,Assumptions!$B$33))) | I17: =IF(I$4<=Assumptions!$B$7,0,IF(I$4<=Assumptions!$B$8,Assumptions!$B$31,IF(I$4<=Assumptions!$B$9,Assumptions!$B$32,Assumptions!$B$33))) | ... S17: =IF(S$4<=Assumptions!$B$7,0,IF(S$4<=Assumptions!$B$8,Assumptions!$B$31,IF(S$4<=Assumptions!$B$9,Assumptions!$B$32,Assumptions!$B$33))) | T17: =SUM(B17:S17)
A18: Total signups | B18: =B17 | C18: =B18+C17 | D18: =C18+D17 | E18: =D18+E17 | F18: =E18+F17 | G18: =F18+G17 | H18: =G18+H17 | I18: =H18+I17 | J18: =I18+J17 | ... S18: =R18+S17
A19: Monthly active users | B19: =ROUND(B18*Assumptions!$B$34,0) | C19: =ROUND(C18*Assumptions!$B$34,0) | D19: =ROUND(D18*Assumptions!$B$34,0) | E19: =ROUND(E18*Assumptions!$B$34,0) | F19: =ROUND(F18*Assumptions!$B$34,0) | G19: =ROUND(G18*Assumptions!$B$34,0) | H19: =ROUND(H18*Assumptions!$B$34,0) | I19: =ROUND(I18*Assumptions!$B$34,0) | ... S19: =ROUND(S18*Assumptions!$B$34,0)
A20: Paying users | B20: =IF(B$4>=Assumptions!$B$10,ROUND(B19*Assumptions!$B$35,0),0) | C20: =IF(C$4>=Assumptions!$B$10,ROUND(C19*Assumptions!$B$35,0),0) | D20: =IF(D$4>=Assumptions!$B$10,ROUND(D19*Assumptions!$B$35,0),0) | E20: =IF(E$4>=Assumptions!$B$10,ROUND(E19*Assumptions!$B$35,0),0) | F20: =IF(F$4>=Assumptions!$B$10,ROUND(F19*Assumptions!$B$35,0),0) | G20: =IF(G$4>=Assumptions!$B$10,ROUND(G19*Assumptions!$B$35,0),0) | H20: =IF(H$4>=Assumptions!$B$10,ROUND(H19*Assumptions!$B$35,0),0) | I20: =IF(I$4>=Assumptions!$B$10,ROUND(I19*Assumptions!$B$35,0),0) | ... S20: =IF(S$4>=Assumptions!$B$10,ROUND(S19*Assumptions!$B$35,0),0)
A21: Revenue
A22: Heartbeat+ gross bookings (incl. GST) | B22: =B20*Assumptions!$B$40 | C22: =C20*Assumptions!$B$40 | D22: =D20*Assumptions!$B$40 | E22: =E20*Assumptions!$B$40 | F22: =F20*Assumptions!$B$40 | G22: =G20*Assumptions!$B$40 | H22: =H20*Assumptions!$B$40 | I22: =I20*Assumptions!$B$40 | ... S22: =S20*Assumptions!$B$40 | T22: =SUM(B22:S22)
A23: Less GST | B23: =-(B22-B22/(1+Assumptions!$B$41)) | C23: =-(C22-C22/(1+Assumptions!$B$41)) | D23: =-(D22-D22/(1+Assumptions!$B$41)) | E23: =-(E22-E22/(1+Assumptions!$B$41)) | F23: =-(F22-F22/(1+Assumptions!$B$41)) | G23: =-(G22-G22/(1+Assumptions!$B$41)) | H23: =-(H22-H22/(1+Assumptions!$B$41)) | I23: =-(I22-I22/(1+Assumptions!$B$41)) | ... S23: =-(S22-S22/(1+Assumptions!$B$41)) | T23: =SUM(B23:S23)
A24: Less payment fees | B24: =-B22*Assumptions!$B$42 | C24: =-C22*Assumptions!$B$42 | D24: =-D22*Assumptions!$B$42 | E24: =-E22*Assumptions!$B$42 | F24: =-F22*Assumptions!$B$42 | G24: =-G22*Assumptions!$B$42 | H24: =-H22*Assumptions!$B$42 | I24: =-I22*Assumptions!$B$42 | ... S24: =-S22*Assumptions!$B$42 | T24: =SUM(B24:S24)
A25: Heartbeat+ net revenue | B25: =B22+B23+B24 | C25: =C22+C23+C24 | D25: =D22+D23+D24 | E25: =E22+E23+E24 | F25: =F22+F23+F24 | G25: =G22+G23+G24 | H25: =H22+H23+H24 | I25: =I22+I23+I24 | ... S25: =S22+S23+S24 | T25: =SUM(B25:S25)
A26: Free monthly active users | B26: =B19-B20 | C26: =C19-C20 | D26: =D19-D20 | E26: =E19-E20 | F26: =F19-F20 | G26: =G19-G20 | H26: =H19-H20 | I26: =I19-I20 | ... S26: =S19-S20
A27: Ad revenue | B27: =IF(B$4>=Assumptions!$B$44,B26/1000*(Assumptions!$B$45*Assumptions!$B$46+Assumptions!$B$47*Assumptions!$B$48),0) | C27: =IF(C$4>=Assumptions!$B$44,C26/1000*(Assumptions!$B$45*Assumptions!$B$46+Assumptions!$B$47*Assumptions!$B$48),0) | D27: =IF(D$4>=Assumptions!$B$44,D26/1000*(Assumptions!$B$45*Assumptions!$B$46+Assumptions!$B$47*Assumptions!$B$48),0) | E27: =IF(E$4>=Assumptions!$B$44,E26/1000*(Assumptions!$B$45*Assumptions!$B$46+Assumptions!$B$47*Assumptions!$B$48),0) | F27: =IF(F$4>=Assumptions!$B$44,F26/1000*(Assumptions!$B$45*Assumptions!$B$46+Assumptions!$B$47*Assumptions!$B$48),0) | G27: =IF(G$4>=Assumptions!$B$44,G26/1000*(Assumptions!$B$45*Assumptions!$B$46+Assumptions!$B$47*Assumptions!$B$48),0) | H27: =IF(H$4>=Assumptions!$B$44,H26/1000*(Assumptions!$B$45*Assumptions!$B$46+Assumptions!$B$47*Assumptions!$B$48),0) | I27: =IF(I$4>=Assumptions!$B$44,I26/1000*(Assumptions!$B$45*Assumptions!$B$46+Assumptions!$B$47*Assumptions!$B$48),0) | ... S27: =IF(S$4>=Assumptions!$B$44,S26/1000*(Assumptions!$B$45*Assumptions!$B$46+Assumptions!$B$47*Assumptions!$B$48),0) | T27: =SUM(B27:S27)
A28: Affiliate commission | B28: =IF(B$4>=Assumptions!$B$50,B19*Assumptions!$B$51*Assumptions!$B$52*Assumptions!$B$53*Assumptions!$B$54*Assumptions!$B$55,0) | C28: =IF(C$4>=Assumptions!$B$50,C19*Assumptions!$B$51*Assumptions!$B$52*Assumptions!$B$53*Assumptions!$B$54*Assumptions!$B$55,0) | D28: =IF(D$4>=Assumptions!$B$50,D19*Assumptions!$B$51*Assumptions!$B$52*Assumptions!$B$53*Assumptions!$B$54*Assumptions!$B$55,0) | E28: =IF(E$4>=Assumptions!$B$50,E19*Assumptions!$B$51*Assumptions!$B$52*Assumptions!$B$53*Assumptions!$B$54*Assumptions!$B$55,0) | F28: =IF(F$4>=Assumptions!$B$50,F19*Assumptions!$B$51*Assumptions!$B$52*Assumptions!$B$53*Assumptions!$B$54*Assumptions!$B$55,0) | G28: =IF(G$4>=Assumptions!$B$50,G19*Assumptions!$B$51*Assumptions!$B$52*Assumptions!$B$53*Assumptions!$B$54*Assumptions!$B$55,0) | H28: =IF(H$4>=Assumptions!$B$50,H19*Assumptions!$B$51*Assumptions!$B$52*Assumptions!$B$53*Assumptions!$B$54*Assumptions!$B$55,0) | I28: =IF(I$4>=Assumptions!$B$50,I19*Assumptions!$B$51*Assumptions!$B$52*Assumptions!$B$53*Assumptions!$B$54*Assumptions!$B$55,0) | ... S28: =IF(S$4>=Assumptions!$B$50,S19*Assumptions!$B$51*Assumptions!$B$52*Assumptions!$B$53*Assumptions!$B$54*Assumptions!$B$55,0) | T28: =SUM(B28:S28)
A29: Total net revenue | B29: =B25+B27+B28 | C29: =C25+C27+C28 | D29: =D25+D27+D28 | E29: =E25+E27+E28 | F29: =F25+F27+F28 | G29: =G25+G27+G28 | H29: =H25+H27+H28 | I29: =I25+I27+I28 | ... S29: =S25+S27+S28 | T29: =SUM(B29:S29)
A30: Cash
A31: Net burn (costs minus net revenue) | B31: =B15-B29 | C31: =C15-C29 | D31: =D15-D29 | E31: =E15-E29 | F31: =F15-F29 | G31: =G15-G29 | H31: =H15-H29 | I31: =I15-I29 | ... S31: =S15-S29 | T31: =SUM(B31:S31)
A32: Cash at end of month | B32: =Assumptions!$B$5-B31 | C32: =B32-C31 | D32: =C32-D31 | E32: =D32-E31 | F32: =E32-F31 | G32: =F32-G31 | H32: =G32-H31 | I32: =H32-I31 | J32: =I32-J31 | ... S32: =R32-S31

Sheet Use of Funds
A1: Use of funds and headline numbers
A3: Category | B3: 18-month total (₹) | C3: % of raise
A4: Team (founder + 3 roles) | B4: =Monthly!T7+Monthly!T8+Monthly!T9+Monthly!T10 | C4: =IF(Assumptions!$B$5=0,0,B4/Assumptions!$B$5)
A5: Marketing and community | B5: =Monthly!T11 | C5: =IF(Assumptions!$B$5=0,0,B5/Assumptions!$B$5)
A6: Infrastructure | B6: =Monthly!T12 | C6: =IF(Assumptions!$B$5=0,0,B6/Assumptions!$B$5)
A7: Legal, accounting and compliance | B7: =Monthly!T13 | C7: =IF(Assumptions!$B$5=0,0,B7/Assumptions!$B$5)
A8: Tools, devices and misc | B8: =Monthly!T14 | C8: =IF(Assumptions!$B$5=0,0,B8/Assumptions!$B$5)
A9: Total costs | B9: =SUM(B4:B8) | C9: =IF(Assumptions!$B$5=0,0,B9/Assumptions!$B$5)
A11: Headline numbers
A12: Raise | B12: =Assumptions!$B$5
A13: Net revenue over 18 months | B13: =Monthly!T29
A14: from Heartbeat+ | B14: =Monthly!T25
A15: from ads | B15: =Monthly!T27
A16: from affiliate commission | B16: =Monthly!T28
A17: Net burn over 18 months | B17: =Monthly!T31
A18: Cash left at month 18 (buffer) | B18: =Monthly!S32
A19: Lowest cash balance in any month | B19: =MIN(Monthly!B32:S32)
A20: Total signups by month 18 | B20: =Monthly!S18
A21: Monthly active users at month 18 | B21: =Monthly!S19
A22: Paying users at month 18 | B22: =Monthly!S20
A23: Monthly net revenue at month 18 | B23: =Monthly!S29
A24: Average monthly burn | B24: =Monthly!T31/18
A26: This is a plan, not a forecast. Growth and conversion are assumptions to be tested in the closed beta; the point of the round is to prove them.

Sheet Sources
A1: Sources for market figures used in the deck
A3: Fact | B3: Source | C3: Link
A4: Paying users are typically 5–15% of MAU on Indian dating apps; online dating ₹2,000–2,500 Cr by 2030 at 12–14% a year; women ~26% of users; 75%+ of Gen Z report swiping fatigue | B4: Redseer, Dec 2025 | C4: https://redseer.com/articles/whos-winning-in-indias-dating-matrimony-market-and-where-are-the-opportunities-for-platforms-and-investors/
A5: India dating apps market US$788M (2024), US$1.42B by 2030 | B5: MarkNtel Advisors | C5: https://www.marknteladvisors.com/press-release/india-dating-apps-market-size
A6: India online dating app market US$547.9M (2023), US$1,015M by 2030 | B6: Grand View Research | C6: https://www.grandviewresearch.com/horizon/outlook/online-dating-application-market/india
A7: Aisle: Info Edge bought 76% for ₹91 Cr (2022); FY25 revenue ₹39.6 Cr; weekly plans from ₹99 | B7: Business Today; Storyboard18; Global Dating Insights | C7: https://www.businesstoday.in/entrepreneurship/news/story/infoedge-acquires-76-stake-in-dating-app-aisle-for-rs-91-cr-325207-2022-03-08
A8: Hinge: India is its #2 market by downloads; Hinge+ ₹1,199/month | B8: Global Dating Insights, Sep 2026 | C8: https://www.globaldatinginsights.com/from-the-web/hinge-india-second-largest-market/
A9: Hinge paying users +17% while Match Group total fell 5% (Q4 2025) | B9: Match Group Q4 2025 results | C9: https://finviz.com/news/298114/match-group-announces-fourth-quarter-and-full-year-results
A10: TrulyMadly revenue ₹12.3 Cr (FY25), ~US$8.9M raised | B10: Inc42 | C10: https://inc42.com/company/trulymadly/
A11: FRND (game-like audio dating) US$6.5M Series A led by KRAFTON | B11: YourStory, Dec 2021 | C11: https://yourstory.com/2021/12/bengaluru-dating-app-audio-romance-frnd-series-a-funding-krafton
A12: Amazon Associates India fee schedule: apparel 7.5%, shoes and jewellery 7%, beauty 8%; 24-hour cookie | B12: Amazon Associates India (Oct 2026) | C12: https://affiliate-program.amazon.in/help/operating/advertisingfees/
A13: Flipkart Affiliate: fashion and lifestyle 8% | B13: Flipkart Affiliate (Oct 2026) | C13: https://affiliate.flipkart.com/commissions
A14: Myntra via Cuelinks: 7.5% new users, 3.75% existing; 1-day cookie | B14: Cuelinks (2026) | C14: https://www.cuelinks.com/campaigns/myntra-affiliate-program
... A21: Aisle weekly plans from ₹99 | B21: Global Dating Insights, Jul 2025 | C21: https://www.globaldatinginsights.com/featured/aisle-network-marks-11th-anniversary-with-changes-to-premium-model/
